Workbook

Sheet Apple_FCF_FY2025
B1: Student: Truc Anh Nguyen - 0873760
B2: APPLE INC. — FREE CASH FLOW CALCULATION
B3: Fiscal Year Ended September 27, 2025 (FY2025)
B4: Source: Apple Inc. 10-K Annual Report, Filed with SEC
B6: Line Item | C6: Amount ($M) | D6: Basis / Formula
B7: I. CASH GENERATED BY OPERATING ACTIVITIES
B8: Net Income | C8: 112010 | D8: 10-K: Consolidated Statements of Operations
B9: (+) Depreciation & Amortization | C9: 11698 | D9: Non-cash charge added back
B10: (+) Share-Based Compensation | C10: 12863 | D10: Non-cash charge added back
B11: (+) Other Adjustments | C11: -89 | D11: Other non-cash items per 10-K
B12: Changes in Operating Assets & Liabilities:
B13: Accounts Receivable, net | C13: -6682 | D13: Increase in A/R = cash outflow
B14: Vendor Non-Trade Receivables | C14: -347 | D14: Increase = cash outflow
B15: Inventories | C15: 1400 | D15: Decrease in inventory = cash inflow
B16: Other Current & Non-Current Assets | C16: -9197 | D16: Increase in assets = cash outflow
B17: Accounts Payable | C17: 902 | D17: Increase in A/P = cash inflow
B18: Other Current & Non-Current Liabilities | C18: -11076 | D18: Decrease in liabilities = cash outflow
B20: Cash Generated by Operating Activities (CFO) | C20: =SUM(C8:C18) -> 111482 | D20: Sum of all operating items (per 10-K: $111,482M)
B22: II. CAPITAL EXPENDITURES
B23: Purchases of Property, Plant & Equipment (CapEx) | C23: -12715 | D23: 10-K: Cash Flows — Investing Activities ($12,715M)
B25: III. FREE CASH FLOW (FCF)
B27: Free Cash Flow | C27: =C20+C23 -> 98767 | D27: FCF = CFO - CapEx = $111,482M - $12,715M = $98,767M
B29: FORMULA:
B30: Free Cash Flow = Cash from Operations - Capital Expenditures
B31: FCF = $111,482M - $12,715M = $98,767M (~$98.8 Billion)

Sheet Financial_Statements
B1: Student: Truc Anh Nguyen - 0873760
B2: APPLE INC. — CONSOLIDATED FINANCIAL STATEMENTS
B3: Fiscal Year Ended September 27, 2025 (In Millions, USD)
B4: Source: Apple Inc. Form 10-K, SEC Filing
C6: FY2025 | D6: FY2024
B7: CONSOLIDATED STATEMENT OF OPERATIONS
B8: Net Sales (Revenue) | C8: 416161 | D8: 391035
B9: Cost of Sales | C9: -220960 | D9: -210438
B10: Gross Margin | C10: =C8+C9 -> 195201 | D10: =D8+D9 -> 180597
B11: Research & Development | C11: -34550 | D11: -31370
B12: Selling, General & Administrative | C12: -27601 | D12: -26146
B13: Total Operating Expenses | C13: =C11+C12 -> -62151 | D13: =D11+D12 -> -57516
B14: Operating Income | C14: =C10+C13 -> 133050 | D14: =D10+D13 -> 123081
B15: Other Income/(Expense), Net | C15: -321 | D15: -382
B16: Income Before Provision for Income Taxes | C16: =C14+C15 -> 132729 | D16: =D14+D15 -> 122699
B17: Provision for Income Taxes | C17: -20719 | D17: -28963
B18: Net Income | C18: =C16+C17 -> 112010 | D18: =D16+D17 -> 93736
B20: CONSOLIDATED BALANCE SHEET
B21: ASSETS
B22: Cash & Cash Equivalents | C22: 35934 | D22: 29943
B23: Marketable Securities (Current) | C23: 18763 | D23: 35228
B24: Accounts Receivable, Net | C24: 39777 | D24: 33410
B25: Vendor Non-Trade Receivables | C25: 33180 | D25: 32833
B26: Inventories | C26: 5718 | D26: 7286
B27: Other Current Assets | C27: 14585 | D27: 14287
B28: Total Current Assets | C28: =SUM(C22:C27) -> 147957 | D28: =SUM(D22:D27) -> 152987
B29: Marketable Securities (Non-Current) | C29: 77723 | D29: 91479
B30: Property, Plant & Equipment, Net | C30: 49834 | D30: 45680
B31: Other Non-Current Assets | C31: 83727 | D31: 74834
B32: Total Non-Current Assets | C32: =SUM(C29:C31) -> 211284 | D32: =SUM(D29:D31) -> 211993
B33: Total Assets | C33: =C28+C32 -> 359241 | D33: =D28+D32 -> 364980
B34: LIABILITIES & SHAREHOLDERS' EQUITY
B35: Accounts Payable | C35: 69860 | D35: 68960
B36: Other Current Liabilities | C36: 66387 | D36: 78304
B37: Deferred Revenue (Current) | C37: 9055 | D37: 8249
B38: Commercial Paper | C38: 7979 | D38: 9967
B39: Term Debt (Current) | C39: 12350 | D39: 10912
B40: Total Current Liabilities | C40: =SUM(C35:C39) -> 165631 | D40: =SUM(D35:D39) -> 176392
B41: Term Debt (Non-Current) | C41: 78328 | D41: 85750
B42: Other Non-Current Liabilities | C42: 41549 | D42: 45888
...

Sheet Financials-2025-Clean
A1: Student: Truc Anh Nguyen - 0873760
A3: APPLE 2025 ANNUAL REPORT
A5: Financial Information | E5: Ratio Calculations | I5: WACC + Intrinsic Value
A6: Item | B6: Value | E6: Ratio | F6: Value | I6: Item | J6: Value | K6: Note
A7: Revenue | B7: {=Financial_Statements!C8} -> 416161 | E7: Gross Profit Margin | F7: =(B7-B8)/B7 -> 0.46905164 | I7: FCF | J7: {=B21} -> 98767 | K7: Unit: million USD
A8: COGS | B8: =-Financial_Statements!C9 -> 220960 | E8: Operating Profit Margin | F8: =B9/B7 -> 0.319708 | I8: Cost of Equity (Ke) | J8: =B23+B22*(B24-B23) -> 0.16082 | K8: CAPM: Rf + β(Rm-Rf)
A9: Operating Income | B9: {=Financial_Statements!C14} -> 133050 | E9: Net Profit Margin | F9: =B10/B7 -> 0.26915064 | I9: Cost of Debt (Kd) | J9: {=B25} -> 0.0556 | K9: From 10-K Note 9 (weighted-avg effective rate)
A10: Net Income | B10: {=Financial_Statements!C18} -> 112010 | E10: Return on Assets (ROA) | F10: =B10/B11 -> 0.31179626 | I10: Tax Rate | J10: =ABS(Financial_Statements!C17/Financial_Statements!C16) -> 0.15610002 | K10: Tax Provision / Pre-tax Income
A11: Total Assets | B11: {=Financial_Statements!C33} -> 359241 | E11: Return on Equity (ROE) | F11: =B10/B13 -> 1.5191298 | I11: Market Cap (E) | J11: =B19*B20 -> 3816062.2 | K11: Shares × Price per Share
A12: Total Liabilities | B12: {=Financial_Statements!C44} -> 285508 | E12: Earnings per Share (EPS) | F12: =B10/B19 -> 7.4598735 | I12: Total Debt (D) | J12: {=B26} -> 98657 | K12: CP + Term Debt (Current + NC)
A13: Shareholder Equity | B13: {=Financial_Statements!C48} -> 73733 | E13: Current Ratio | F13: =B14/B16 -> 0.89329292 | I13: Total Value (V = E+D) | J13: =J11+J12 -> 3914719.2
A14: Current Assets | B14: {=Financial_Statements!C28} -> 147957 | E14: Quick Ratio | F14: =(B14-B15)/B16 -> 0.8587704 | I14: WACC | J14: =(J11/J13)*J8+(J12/J13)*J9*(1-J10) -> 0.15794956 | K14: (E/V)×Ke + (D/V)×Kd×(1-T)
A15: Inventories | B15: {=Financial_Statements!C26} -> 5718 | E15: Cash Ratio | F15: =B17/B16 -> 0.21695214 | I15: Intrinsic Firm Value | J15: =J7/J14 -> 625307.2 | K15: FCF ÷ WACC
A16: Current Liabilities | B16: {=Financial_Statements!C40} -> 165631 | E16: P/E Ratio | F16: =B20/F12 -> 34.068943 | I16: Shares Outstanding | J16: {=B19} -> 15015 | K16: Unit: million shares
A17: Cash and Equivalents | B17: {=Financial_Statements!C22} -> 35934 | E17: Dividend Payout Ratio | F17: =B18/B10 -> 0.13767521 | I17: Value per Share | J17: =J15/J16 -> 41.645501 | K17: Firm Value ÷ Shares
A18: Dividends | B18: =-Financial_Statements!C73 -> 15421 | E18: Debt-to-Equity Ratio | F18: =B12/B13 -> 3.8721875
A19: Shares Outstanding | B19: 15015 | E19: Sustainable Growth Rate | F19: =F11*(1-F17) -> 1.3099833
A20: Price per Share | B20: 254.15
A21: Free Cash Flow | B21: {=Financial_Statements!C82} -> 98767
A22: Beta | B22: 1.2
A23: Risk-Free Rate (10Y Treasury) | B23: 0.0269
A24: Market Return (S&P500 10Y avg) | B24: 0.1385
A25: Cost of Debt (Kd) | B25: 0.0556
A26: Total Debt | B26: 98657
